OpenJDK Server VM warning: You have loaded library /usr/local/hadoop/lib/native/libhadoop.so.1.0.0 which might have disabled stack guard. The VM will try to fix the stack guard now.
It's highly recommended that you fix the library with 'execstack -c <libfile>', or link it with '-z noexecstack'.
java.io.IOException: Inconsistent checkpoint fields.
LV = -60 namespaceID = 1923499524 cTime = 0 ; clusterId = CID-f3b9f4ac-c883-45fe-9424-5b87f022e401 ; blockpoolId = BP-410769465-127.0.0.1-1424768430150.
Expecting respectively: -60; 495027567; 0; CID-975390f8-7f1e-4999-bafb-d1e845945f41; BP-762311704-127.0.0.1-1424753988129.
	at org.apache.hadoop.hdfs.server.namenode.CheckpointSignature.validateStorageInfo(CheckpointSignature.java:134)
	at org.apache.hadoop.hdfs.server.namenode.SecondaryNameNode.doCheckpoint(SecondaryNameNode.java:531)
	at org.apache.hadoop.hdfs.server.namenode.SecondaryNameNode.doWork(SecondaryNameNode.java:395)
	at org.apache.hadoop.hdfs.server.namenode.SecondaryNameNode$1.run(SecondaryNameNode.java:361)
	at org.apache.hadoop.security.SecurityUtil.doAsLoginUserOrFatal(SecurityUtil.java:412)
	at org.apache.hadoop.hdfs.server.namenode.SecondaryNameNode.run(SecondaryNameNode.java:357)
	at java.lang.Thread.run(Thread.java:745)
java.io.IOException: Inconsistent checkpoint fields.
LV = -60 namespaceID = 1923499524 cTime = 0 ; clusterId = CID-f3b9f4ac-c883-45fe-9424-5b87f022e401 ; blockpoolId = BP-410769465-127.0.0.1-1424768430150.
Expecting respectively: -60; 495027567; 0; CID-975390f8-7f1e-4999-bafb-d1e845945f41; BP-762311704-127.0.0.1-1424753988129.
	at org.apache.hadoop.hdfs.server.namenode.CheckpointSignature.validateStorageInfo(CheckpointSignature.java:134)
	at org.apache.hadoop.hdfs.server.namenode.SecondaryNameNode.doCheckpoint(SecondaryNameNode.java:531)
	at org.apache.hadoop.hdfs.server.namenode.SecondaryNameNode.doWork(SecondaryNameNode.java:395)
	at org.apache.hadoop.hdfs.server.namenode.SecondaryNameNode$1.run(SecondaryNameNode.java:361)
	at org.apache.hadoop.security.SecurityUtil.doAsLoginUserOrFatal(SecurityUtil.java:412)
	at org.apache.hadoop.hdfs.server.namenode.SecondaryNameNode.run(SecondaryNameNode.java:357)
	at java.lang.Thread.run(Thread.java:745)
java.io.IOException: Inconsistent checkpoint fields.
LV = -60 namespaceID = 1923499524 cTime = 0 ; clusterId = CID-f3b9f4ac-c883-45fe-9424-5b87f022e401 ; blockpoolId = BP-410769465-127.0.0.1-1424768430150.
Expecting respectively: -60; 495027567; 0; CID-975390f8-7f1e-4999-bafb-d1e845945f41; BP-762311704-127.0.0.1-1424753988129.
	at org.apache.hadoop.hdfs.server.namenode.CheckpointSignature.validateStorageInfo(CheckpointSignature.java:134)
	at org.apache.hadoop.hdfs.server.namenode.SecondaryNameNode.doCheckpoint(SecondaryNameNode.java:531)
	at org.apache.hadoop.hdfs.server.namenode.SecondaryNameNode.doWork(SecondaryNameNode.java:395)
	at org.apache.hadoop.hdfs.server.namenode.SecondaryNameNode$1.run(SecondaryNameNode.java:361)
	at org.apache.hadoop.security.SecurityUtil.doAsLoginUserOrFatal(SecurityUtil.java:412)
	at org.apache.hadoop.hdfs.server.namenode.SecondaryNameNode.run(SecondaryNameNode.java:357)
	at java.lang.Thread.run(Thread.java:745)
java.io.IOException: Inconsistent checkpoint fields.
LV = -60 namespaceID = 1923499524 cTime = 0 ; clusterId = CID-f3b9f4ac-c883-45fe-9424-5b87f022e401 ; blockpoolId = BP-410769465-127.0.0.1-1424768430150.
Expecting respectively: -60; 495027567; 0; CID-975390f8-7f1e-4999-bafb-d1e845945f41; BP-762311704-127.0.0.1-1424753988129.
	at org.apache.hadoop.hdfs.server.namenode.CheckpointSignature.validateStorageInfo(CheckpointSignature.java:134)
	at org.apache.hadoop.hdfs.server.namenode.SecondaryNameNode.doCheckpoint(SecondaryNameNode.java:531)
	at org.apache.hadoop.hdfs.server.namenode.SecondaryNameNode.doWork(SecondaryNameNode.java:395)
	at org.apache.hadoop.hdfs.server.namenode.SecondaryNameNode$1.run(SecondaryNameNode.java:361)
	at org.apache.hadoop.security.SecurityUtil.doAsLoginUserOrFatal(SecurityUtil.java:412)
	at org.apache.hadoop.hdfs.server.namenode.SecondaryNameNode.run(SecondaryNameNode.java:357)
	at java.lang.Thread.run(Thread.java:745)
java.net.ConnectException: Call From shrinivaasanka-Inspiron-1545/127.0.0.1 to localhost:9000 failed on connection exception: java.net.ConnectException: Connection refused; For more details see:  http://wiki.apache.org/hadoop/ConnectionRefused
	at sun.reflect.NativeConstructorAccessorImpl.newInstance0(Native Method)
	at sun.reflect.NativeConstructorAccessorImpl.newInstance(NativeConstructorAccessorImpl.java:57)
	at sun.reflect.DelegatingConstructorAccessorImpl.newInstance(DelegatingConstructorAccessorImpl.java:45)
	at java.lang.reflect.Constructor.newInstance(Constructor.java:526)
	at org.apache.hadoop.net.NetUtils.wrapWithMessage(NetUtils.java:791)
	at org.apache.hadoop.net.NetUtils.wrapException(NetUtils.java:731)
	at org.apache.hadoop.ipc.Client.call(Client.java:1472)
	at org.apache.hadoop.ipc.Client.call(Client.java:1399)
	at org.apache.hadoop.ipc.ProtobufRpcEngine$Invoker.invoke(ProtobufRpcEngine.java:232)
	at com.sun.proxy.$Proxy9.getTransactionId(Unknown Source)
	at org.apache.hadoop.hdfs.protocolPB.NamenodeProtocolTranslatorPB.getTransactionID(NamenodeProtocolTranslatorPB.java:125)
	at sun.reflect.NativeMethodAccessorImpl.invoke0(Native Method)
	at sun.reflect.NativeMethodAccessorImpl.invoke(NativeMethodAccessorImpl.java:57)
	at sun.reflect.DelegatingMethodAccessorImpl.invoke(DelegatingMethodAccessorImpl.java:43)
	at java.lang.reflect.Method.invoke(Method.java:606)
	at org.apache.hadoop.io.retry.RetryInvocationHandler.invokeMethod(RetryInvocationHandler.java:187)
	at org.apache.hadoop.io.retry.RetryInvocationHandler.invoke(RetryInvocationHandler.java:102)
	at com.sun.proxy.$Proxy10.getTransactionID(Unknown Source)
	at org.apache.hadoop.hdfs.server.namenode.SecondaryNameNode.countUncheckpointedTxns(SecondaryNameNode.java:641)
	at org.apache.hadoop.hdfs.server.namenode.SecondaryNameNode.shouldCheckpointBasedOnCount(SecondaryNameNode.java:649)
	at org.apache.hadoop.hdfs.server.namenode.SecondaryNameNode.doWork(SecondaryNameNode.java:393)
	at org.apache.hadoop.hdfs.server.namenode.SecondaryNameNode$1.run(SecondaryNameNode.java:361)
	at org.apache.hadoop.security.SecurityUtil.doAsLoginUserOrFatal(SecurityUtil.java:412)
	at org.apache.hadoop.hdfs.server.namenode.SecondaryNameNode.run(SecondaryNameNode.java:357)
	at java.lang.Thread.run(Thread.java:745)
Caused by: java.net.ConnectException: Connection refused
	at sun.nio.ch.SocketChannelImpl.checkConnect(Native Method)
	at sun.nio.ch.SocketChannelImpl.finishConnect(SocketChannelImpl.java:739)
	at org.apache.hadoop.net.SocketIOWithTimeout.connect(SocketIOWithTimeout.java:206)
	at org.apache.hadoop.net.NetUtils.connect(NetUtils.java:530)
	at org.apache.hadoop.net.NetUtils.connect(NetUtils.java:494)
	at org.apache.hadoop.ipc.Client$Connection.setupConnection(Client.java:607)
	at org.apache.hadoop.ipc.Client$Connection.setupIOstreams(Client.java:705)
	at org.apache.hadoop.ipc.Client$Connection.access$2800(Client.java:368)
	at org.apache.hadoop.ipc.Client.getConnection(Client.java:1521)
	at org.apache.hadoop.ipc.Client.call(Client.java:1438)
	... 18 more
java.net.ConnectException: Call From shrinivaasanka-Inspiron-1545/127.0.0.1 to localhost:9000 failed on connection exception: java.net.ConnectException: Connection refused; For more details see:  http://wiki.apache.org/hadoop/ConnectionRefused
	at sun.reflect.NativeConstructorAccessorImpl.newInstance0(Native Method)
	at sun.reflect.NativeConstructorAccessorImpl.newInstance(NativeConstructorAccessorImpl.java:57)
	at sun.reflect.DelegatingConstructorAccessorImpl.newInstance(DelegatingConstructorAccessorImpl.java:45)
	at java.lang.reflect.Constructor.newInstance(Constructor.java:526)
	at org.apache.hadoop.net.NetUtils.wrapWithMessage(NetUtils.java:791)
	at org.apache.hadoop.net.NetUtils.wrapException(NetUtils.java:731)
	at org.apache.hadoop.ipc.Client.call(Client.java:1472)
	at org.apache.hadoop.ipc.Client.call(Client.java:1399)
	at org.apache.hadoop.ipc.ProtobufRpcEngine$Invoker.invoke(ProtobufRpcEngine.java:232)
	at com.sun.proxy.$Proxy9.getTransactionId(Unknown Source)
	at org.apache.hadoop.hdfs.protocolPB.NamenodeProtocolTranslatorPB.getTransactionID(NamenodeProtocolTranslatorPB.java:125)
	at sun.reflect.NativeMethodAccessorImpl.invoke0(Native Method)
	at sun.reflect.NativeMethodAccessorImpl.invoke(NativeMethodAccessorImpl.java:57)
	at sun.reflect.DelegatingMethodAccessorImpl.invoke(DelegatingMethodAccessorImpl.java:43)
	at java.lang.reflect.Method.invoke(Method.java:606)
	at org.apache.hadoop.io.retry.RetryInvocationHandler.invokeMethod(RetryInvocationHandler.java:187)
	at org.apache.hadoop.io.retry.RetryInvocationHandler.invoke(RetryInvocationHandler.java:102)
	at com.sun.proxy.$Proxy10.getTransactionID(Unknown Source)
	at org.apache.hadoop.hdfs.server.namenode.SecondaryNameNode.countUncheckpointedTxns(SecondaryNameNode.java:641)
	at org.apache.hadoop.hdfs.server.namenode.SecondaryNameNode.shouldCheckpointBasedOnCount(SecondaryNameNode.java:649)
	at org.apache.hadoop.hdfs.server.namenode.SecondaryNameNode.doWork(SecondaryNameNode.java:393)
	at org.apache.hadoop.hdfs.server.namenode.SecondaryNameNode$1.run(SecondaryNameNode.java:361)
	at org.apache.hadoop.security.SecurityUtil.doAsLoginUserOrFatal(SecurityUtil.java:412)
	at org.apache.hadoop.hdfs.server.namenode.SecondaryNameNode.run(SecondaryNameNode.java:357)
	at java.lang.Thread.run(Thread.java:745)
Caused by: java.net.ConnectException: Connection refused
	at sun.nio.ch.SocketChannelImpl.checkConnect(Native Method)
	at sun.nio.ch.SocketChannelImpl.finishConnect(SocketChannelImpl.java:739)
	at org.apache.hadoop.net.SocketIOWithTimeout.connect(SocketIOWithTimeout.java:206)
	at org.apache.hadoop.net.NetUtils.connect(NetUtils.java:530)
	at org.apache.hadoop.net.NetUtils.connect(NetUtils.java:494)
	at org.apache.hadoop.ipc.Client$Connection.setupConnection(Client.java:607)
	at org.apache.hadoop.ipc.Client$Connection.setupIOstreams(Client.java:705)
	at org.apache.hadoop.ipc.Client$Connection.access$2800(Client.java:368)
	at org.apache.hadoop.ipc.Client.getConnection(Client.java:1521)
	at org.apache.hadoop.ipc.Client.call(Client.java:1438)
	... 18 more
